Workbook
Name value: Sheet1!$A$7

Sheet helmet
A1: Name | B1: eng | C1: Drop | D1: Base_phy | E1: Base_mag | F1: Base_sta | G1: phy_cor | H1: phy_spi | I1: phy_gra | J1: mag_cor | K1: mag_spi | L1: mag_gra | M1: sta_cor | N1: sta_spi | O1: sta_gra | P1: min_cor | Q1: min_spi | R1: min_gra | S1: phy | T1: mag | U1: sta | V1: Score | W1: Rank
A2: 承种者面具 | B2: ARBEARER'S MASK | C2: 南瓜人 | D2: 4 | E2: 1 | F2: 2 | G2: 3 | J2: 1 | M2: 2 | P2: 22 | S2: =IF(tblHelmet[[#This Row],[Name]]="","", IF( AND( Sheet1!$A$2 >= tblHelmet[[#This Row],[min_cor]], Sheet1!$B$2 >= tblHelmet[[#This Row],[min_spi]], Sheet1!$C$2 >= tblHelmet[[#This Row],[min_gra]] ), _xlfn.FLOOR.MATH( value*tblHelmet[[#This Row],[phy_cor]]*Sheet1!$A$2 + value*tblHelmet[[#This Row],[phy_spi]]*Sheet1!$B$2 + value*tblHelmet[[#This Row],[phy_gra]]*Sheet1!$C$2 ) + tblHelmet[[#This Row],[Base_phy]], tblHelmet[[#This Row],[Base_phy]] )) -> 4 | T2: =IF(tblHelmet[[#This Row],[Name]]="","", IF(AND(Sheet1!$A$2>=tblHelmet[[#This Row],[min_cor]], Sheet1!$B$2>=tblHelmet[[#This Row],[min_spi]], Sheet1!$C$2>=tblHelmet[[#This Row],[min_gra]]), _xlfn.FLOOR.MATH(value*tblHelmet[[#This Row],[mag_cor]]*Sheet1!$A$2 + value*tblHelmet[[#This Row],[mag_spi]]*Sheet1!$B$2 + value*tblHelmet[[#This Row],[mag_gra]]*Sheet1!$C$2) + tblHelmet[[#This Row],[Base_mag]], tblHelmet[[#This Row],[Base_mag]])) -> 1 | U2: =IF(tblHelmet[[#This Row],[Name]]="","", IF(AND(Sheet1!$A$2>=tblHelmet[[#This Row],[min_cor]], Sheet1!$B$2>=tblHelmet[[#This Row],[min_spi]], Sheet1!$C$2>=tblHelmet[[#This Row],[min_gra]]), _xlfn.FLOOR.MATH(value*tblHelmet[[#This Row],[sta_cor]]*Sheet1!$A$2 + value*tblHelmet[[#This Row],[sta_spi]]*Sheet1!$B$2 + value*tblHelmet[[#This Row],[sta_gra]]*Sheet1!$C$2) + tblHelmet[[#This Row],[Base_sta]], tblHelmet[[#This Row],[Base_sta]])) -> 2 | V2: =IF(tblHelmet[[#This Row],[Name]]="","", tblHelmet[[#This Row],[phy]]*Sheet1!$E$2 + tblHelmet[[#This Row],[mag]]*Sheet1!$F$2 + tblHelmet[[#This Row],[sta]]*Sheet1!$G$2) -> 7 | W2: =IF(tblHelmet[[#This Row],[Name]]="","", _xlfn.RANK.EQ(tblHelmet[[#This Row],[Score]], tblHelmet[Score], 0)) -> 9
A3: 奥伦加头盔 | B3: ARMET OF ORENGALL | C3: 集团 | D3: 3 | E3: =2 -> 2 | F3: 3 | G3: 1 | I3: 3 | J3: 1 | L3: 1 | O3: 3 | R3: 20 | S3: =IF(tblHelmet[[#This Row],[Name]]="","", IF( AND( Sheet1!$A$2 >= tblHelmet[[#This Row],[min_cor]], Sheet1!$B$2 >= tblHelmet[[#This Row],[min_spi]], Sheet1!$C$2 >= tblHelmet[[#This Row],[min_gra]] ), _xlfn.FLOOR.MATH( value*tblHelmet[[#This Row],[phy_cor]]*Sheet1!$A$2 + value*tblHelmet[[#This Row],[phy_spi]]*Sheet1!$B$2 + value*tblHelmet[[#This Row],[phy_gra]]*Sheet1!$C$2 ) + tblHelmet[[#This Row],[Base_phy]], tblHelmet[[#This Row],[Base_phy]] )) -> 17 | T3: =IF(tblHelmet[[#This Row],[Name]]="","", IF(AND(Sheet1!$A$2>=tblHelmet[[#This Row],[min_cor]], Sheet1!$B$2>=tblHelmet[[#This Row],[min_spi]], Sheet1!$C$2>=tblHelmet[[#This Row],[min_gra]]), _xlfn.FLOOR.MATH(value*tblHelmet[[#This Row],[mag_cor]]*Sheet1!$A$2 + value*tblHelmet[[#This Row],[mag_spi]]*Sheet1!$B$2 + value*tblHelmet[[#This Row],[mag_gra]]*Sheet1!$C$2) + tblHelmet[[#This Row],[Base_mag]], tblHelmet[[#This Row],[Base_mag]])) -> 7 | U3: =IF(tblHelmet[[#This Row],[Name]]="","", IF(AND(Sheet1!$A$2>=tblHelmet[[#This Row],[min_cor]], Sheet1!$B$2>=tblHelmet[[#This Row],[min_spi]], Sheet1!$C$2>=tblHelmet[[#This Row],[min_gra]]), _xlfn.FLOOR.MATH(value*tblHelmet[[#This Row],[sta_cor]]*Sheet1!$A$2 + value*tblHelmet[[#This Row],[sta_spi]]*Sheet1!$B$2 + value*tblHelmet[[#This Row],[sta_gra]]*Sheet1!$C$2) + tblHelmet[[#This Row],[Base_sta]], tblHelmet[[#This Row],[Base_sta]])) -> 16 | V3: =IF(tblHelmet[[#This Row],[Name]]="","", tblHelmet[[#This Row],[phy]]*Sheet1!$E$2 + tblHelmet[[#This Row],[mag]]*Sheet1!$F$2 + tblHelmet[[#This Row],[sta]]*Sheet1!$G$2) -> 40 | W3: =IF(tblHelmet[[#This Row],[Name]]="","", _xlfn.RANK.EQ(tblHelmet[[#This Row],[Score]], tblHelmet[Score], 0)) -> 1
A4: 苦行者国王头盔 | B4: BASCINET OF THE MENDICANT KING | C4: 乞王 | D4: 3 | E4: 1 | F4: 3 | G4: 3 | H4: 1 | J4: 1 | K4: 2 | M4: 1 | N4: 1 | P4: 20 | S4: =IF(tblHelmet[[#This Row],[Name]]="","", IF( AND( Sheet1!$A$2 >= tblHelmet[[#This Row],[min_cor]], Sheet1!$B$2 >= tblHelmet[[#This Row],[min_spi]], Sheet1!$C$2 >= tblHelmet[[#This Row],[min_gra]] ), _xlfn.FLOOR.MATH( value*tblHelmet[[#This Row],[phy_cor]]*Sheet1!$A$2 + value*tblHelmet[[#This Row],[phy_spi]]*Sheet1!$B$2 + value*tblHelmet[[#This Row],[phy_gra]]*Sheet1!$C$2 ) + tblHelmet[[#This Row],[Base_phy]], tblHelmet[[#This Row],[Base_phy]] )) -> 3 | T4: =IF(tblHelmet[[#This Row],[Name]]="","", IF(AND(Sheet1!$A$2>=tblHelmet[[#This Row],[min_cor]], Sheet1!$B$2>=tblHelmet[[#This Row],[min_spi]], Sheet1!$C$2>=tblHelmet[[#This Row],[min_gra]]), _xlfn.FLOOR.MATH(value*tblHelmet[[#This Row],[mag_cor]]*Sheet1!$A$2 + value*tblHelmet[[#This Row],[mag_spi]]*Sheet1!$B$2 + value*tblHelmet[[#This Row],[mag_gra]]*Sheet1!$C$2) + tblHelmet[[#This Row],[Base_mag]], tblHelmet[[#This Row],[Base_mag]])) -> 1 | U4: =IF(tblHelmet[[#This Row],[Name]]="","", IF(AND(Sheet1!$A$2>=tblHelmet[[#This Row],[min_cor]], Sheet1!$B$2>=tblHelmet[[#This Row],[min_spi]], Sheet1!$C$2>=tblHelmet[[#This Row],[min_gra]]), _xlfn.FLOOR.MATH(value*tblHelmet[[#This Row],[sta_cor]]*Sheet1!$A$2 + value*tblHelmet[[#This Row],[sta_spi]]*Sheet1!$B$2 + value*tblHelmet[[#This Row],[sta_gra]]*Sheet1!$C$2) + tblHelmet[[#This Row],[Base_sta]], tblHelmet[[#This Row],[Base_sta]])) -> 3 | V4: =IF(tblHelmet[[#This Row],[Name]]="","", tblHelmet[[#This Row],[phy]]*Sheet1!$E$2 + tblHelmet[[#This Row],[mag]]*Sheet1!$F$2 + tblHelmet[[#This Row],[sta]]*Sheet1!$G$2) -> 7 | W4: =IF(tblHelmet[[#This Row],[Name]]="","", _xlfn.RANK.EQ(tblHelmet[[#This Row],[Score]], tblHelmet[Score], 0)) -> 9
A5: 铜肺 | B5: BRAZEN LUNG | D5: 2 | E5: 4 | F5: 0 | H5: 1 | K5: 2 | S5: =IF(tblHelmet[[#This Row],[Name]]="","", IF( AND( Sheet1!$A$2 >= tblHelmet[[#This Row],[min_cor]], Sheet1!$B$2 >= tblHelmet[[#This Row],[min_spi]], Sheet1!$C$2 >= tblHelmet[[#This Row],[min_gra]] ), _xlfn.FLOOR.MATH( value*tblHelmet[[#This Row],[phy_cor]]*Sheet1!$A$2 + value*tblHelmet[[#This Row],[phy_spi]]*Sheet1!$B$2 + value*tblHelmet[[#This Row],[phy_gra]]*Sheet1!$C$2 ) + tblHelmet[[#This Row],[Base_phy]], tblHelmet[[#This Row],[Base_phy]] )) -> 2 | T5: =IF(tblHelmet[[#This Row],[Name]]="","", IF(AND(Sheet1!$A$2>=tblHelmet[[#This Row],[min_cor]], Sheet1!$B$2>=tblHelmet[[#This Row],[min_spi]], Sheet1!$C$2>=tblHelmet[[#This Row],[min_gra]]), _xlfn.FLOOR.MATH(value*tblHelmet[[#This Row],[mag_cor]]*Sheet1!$A$2 + value*tblHelmet[[#This Row],[mag_spi]]*Sheet1!$B$2 + value*tblHelmet[[#This Row],[mag_gra]]*Sheet1!$C$2) + tblHelmet[[#This Row],[Base_mag]], tblHelmet[[#This Row],[Base_mag]])) -> 5 | U5: =IF(tblHelmet[[#This Row],[Name]]="","", IF(AND(Sheet1!$A$2>=tblHelmet[[#This Row],[min_cor]], Sheet1!$B$2>=tblHelmet[[#This Row],[min_spi]], Sheet1!$C$2>=tblHelmet[[#This Row],[min_gra]]), _xlfn.FLOOR.MATH(value*tblHelmet[[#This Row],[sta_cor]]*Sheet1!$A$2 + value*tblHelmet[[#This Row],[sta_spi]]*Sheet1!$B$2 + value*tblHelmet[[#This Row],[sta_gra]]*Sheet1!$C$2) + tblHelmet[[#This Row],[Base_sta]], tblHelmet[[#This Row],[Base_sta]])) -> 0 | V5: =IF(tblHelmet[[#This Row],[Name]]="","", tblHelmet[[#This Row],[phy]]*Sheet1!$E$2 + tblHelmet[[#This Row],[mag]]*Sheet1!$F$2 + tblHelmet[[#This Row],[sta]]*Sheet1!$G$2) -> 7 | W5: =IF(tblHelmet[[#This Row],[Name]]="","", _xlfn.RANK.EQ(tblHelmet[[#This Row],[Score]], tblHelmet[Score], 0)) -> 9
A6: 瑟凯德欺诈头盔 | B6: CIRCADE'S HELM OF DECEIT | C6: 墓穴解密 | D6: 4 | E6: 0 | F6: 2 | G6: 3 | I6: 0 | M6: 2 | P6: 14 | S6: =IF(tblHelmet[[#This Row],[Name]]="","", IF( AND( Sheet1!$A$2 >= tblHelmet[[#This Row],[min_cor]], Sheet1!$B$2 >= tblHelmet[[#This Row],[min_spi]], Sheet1!$C$2 >= tblHelmet[[#This Row],[min_gra]] ), _xlfn.FLOOR.MATH( value*tblHelmet[[#This Row],[phy_cor]]*Sheet1!$A$2 + value*tblHelmet[[#This Row],[phy_spi]]*Sheet1!$B$2 + value*tblHelmet[[#This Row],[phy_gra]]*Sheet1!$C$2 ) + tblHelmet[[#This Row],[Base_phy]], tblHelmet[[#This Row],[Base_phy]] )) -> 4 | T6: =IF(tblHelmet[[#This Row],[Name]]="","", IF(AND(Sheet1!$A$2>=tblHelmet[[#This Row],[min_cor]], Sheet1!$B$2>=tblHelmet[[#This Row],[min_spi]], Sheet1!$C$2>=tblHelmet[[#This Row],[min_gra]]), _xlfn.FLOOR.MATH(value*tblHelmet[[#This Row],[mag_cor]]*Sheet1!$A$2 + value*tblHelmet[[#This Row],[mag_spi]]*Sheet1!$B$2 + value*tblHelmet[[#This Row],[mag_gra]]*Sheet1!$C$2) + tblHelmet[[#This Row],[Base_mag]], tblHelmet[[#This Row],[Base_mag]])) -> 0 | U6: =IF(tblHelmet[[#This Row],[Name]]="","", IF(AND(Sheet1!$A$2>=tblHelmet[[#This Row],[min_cor]], Sheet1!$B$2>=tblHelmet[[#This Row],[min_spi]], Sheet1!$C$2>=tblHelmet[[#This Row],[min_gra]]), _xlfn.FLOOR.MATH(value*tblHelmet[[#This Row],[sta_cor]]*Sheet1!$A$2 + value*tblHelmet[[#This Row],[sta_spi]]*Sheet1!$B$2 + value*tblHelmet[[#This Row],[sta_gra]]*Sheet1!$C$2) + tblHelmet[[#This Row],[Base_sta]], tblHelmet[[#This Row],[Base_sta]])) -> 2 | V6: =IF(tblHelmet[[#This Row],[Name]]="","", tblHelmet[[#This Row],[phy]]*Sheet1!$E$2 + tblHelmet[[#This Row],[mag]]*Sheet1!$F$2 + tblHelmet[[#This Row],[sta]]*Sheet1!$G$2) -> 6 | W6: =IF(tblHelmet[[#This Row],[Name]]="","", _xlfn.RANK.EQ(tblHelmet[[#This Row],[Score]], tblHelmet[Score], 0)) -> 17
A7: ！无法获得 | B7: CRONE CUCURBITA MASK | C7: 某个节日 | D7: 3 | E7: 3 | F7: 1 | G7: 2 | H7: 2 | J7: 2 | K7: 2 | O7: 1 | Q7: 12 | S7: =IF(tblHelmet[[#This Row],[Name]]="","", IF( AND( Sheet1!$A$2 >= tblHelmet[[#This Row],[min_cor]], Sheet1!$B$2 >= tblHelmet[[#This Row],[min_spi]], Sheet1!$C$2 >= tblHelmet[[#This Row],[min_gra]] ), _xlfn.FLOOR.MATH( value*tblHelmet[[#This Row],[phy_cor]]*Sheet1!$A$2 + value*tblHelmet[[#This Row],[phy_spi]]*Sheet1!$B$2 + value*tblHelmet[[#This Row],[phy_gra]]*Sheet1!$C$2 ) + tblHelmet[[#This Row],[Base_phy]], tblHelmet[[#This Row],[Base_phy]] )) -> 3 | T7: =IF(tblHelmet[[#This Row],[Name]]="","", IF(AND(Sheet1!$A$2>=tblHelmet[[#This Row],[min_cor]], Sheet1!$B$2>=tblHelmet[[#This Row],[min_spi]], Sheet1!$C$2>=tblHelmet[[#This Row],[min_gra]]), _xlfn.FLOOR.MATH(value*tblHelmet[[#This Row],[mag_cor]]*Sheet1!$A$2 + value*tblHelmet[[#This Row],[mag_spi]]*Sheet1!$B$2 + value*tblHelmet[[#This Row],[mag_gra]]*Sheet1!$C$2) + tblHelmet[[#This Row],[Base_mag]], tblHelmet[[#This Row],[Base_mag]])) -> 3 | U7: =IF(tblHelmet[[#This Row],[Name]]="","", IF(AND(Sheet1!$A$2>=tblHelmet[[#This Row],[min_cor]], Sheet1!$B$2>=tblHelmet[[#This Row],[min_spi]], Sheet1!$C$2>=tblHelmet[[#This Row],[min_gra]]), _xlfn.FLOOR.MATH(value*tblHelmet[[#This Row],[sta_cor]]*Sheet1!$A$2 + value*tblHelmet[[#This Row],[sta_spi]]*Sheet1!$B$2 + value*tblHelmet[[#This Row],[sta_gra]]*Sheet1!$C$2) + tblHelmet[[#This Row],[Base_sta]], tblHelmet[[#This Row],[Base_sta]])) -> 1 | V7: =IF(tblHelmet[[#This Row],[Name]]="","", tblHelmet[[#This Row],[phy]]*Sheet1!$E$2 + tblHelmet[[#This Row],[mag]]*Sheet1!$F$2 + tblHelmet[[#This Row],[sta]]*Sheet1!$G$2) -> 7 | W7: =IF(tblHelmet[[#This Row],[Name]]="","", _xlfn.RANK.EQ(tblHelmet[[#This Row],[Score]], tblHelmet[Score], 0)) -> 9
A8: 忘焰面罩 | B8: FORGETFIRE VISARD | C8: 集团 | D8: 3 | E8: 0 | F8: 3 | G8: 2 | M8: 2 | P8: 12 | S8: =IF(tblHelmet[[#This Row],[Name]]="","", IF( AND( Sheet1!$A$2 >= tblHelmet[[#This Row],[min_cor]], Sheet1!$B$2 >= tblHelmet[[#This Row],[min_spi]], Sheet1!$C$2 >= tblHelmet[[#This Row],[min_gra]] ), _xlfn.FLOOR.MATH( value*tblHelmet[[#This Row],[phy_cor]]*Sheet1!$A$2 + value*tblHelmet[[#This Row],[phy_spi]]*Sheet1!$B$2 + value*tblHelmet[[#This Row],[phy_gra]]*Sheet1!$C$2 ) + tblHelmet[[#This Row],[Base_phy]], tblHelmet[[#This Row],[Base_phy]] )) -> 3 | T8: =IF(tblHelmet[[#This Row],[Name]]="","", IF(AND(Sheet1!$A$2>=tblHelmet[[#This Row],[min_cor]], Sheet1!$B$2>=tblHelmet[[#This Row],[min_spi]], Sheet1!$C$2>=tblHelmet[[#This Row],[min_gra]]), _xlfn.FLOOR.MATH(value*tblHelmet[[#This Row],[mag_cor]]*Sheet1!$A$2 + value*tblHelmet[[#This Row],[mag_spi]]*Sheet1!$B$2 + value*tblHelmet[[#This Row],[mag_gra]]*Sheet1!$C$2) + tblHelmet[[#This Row],[Base_mag]], tblHelmet[[#This Row],[Base_mag]])) -> 0 | U8: =IF(tblHelmet[[#This Row],[Name]]="","", IF(AND(Sheet1!$A$2>=tblHelmet[[#This Row],[min_cor]], Sheet1!$B$2>=tblHelmet[[#This Row],[min_spi]], Sheet1!$C$2>=tblHelmet[[#This Row],[min_gra]]), _xlfn.FLOOR.MATH(value*tblHelmet[[#This Row],[sta_cor]]*Sheet1!$A$2 + value*tblHelmet[[#This Row],[sta_spi]]*Sheet1!$B$2 + value*tblHelmet[[#This Row],[sta_gra]]*Sheet1!$C$2) + tblHelmet[[#This Row],[Base_sta]], tblHelmet[[#This Row],[Base_sta]])) -> 3 | V8: =IF(tblHelmet[[#This Row],[Name]]="","", tblHelmet[[#This Row],[phy]]*Sheet1!$E$2 + tblHelmet[[#This Row],[mag]]*Sheet1!$F$2 + tblHelmet[[#This Row],[sta]]*Sheet1!$G$2) -> 6 | W8: =IF(tblHelmet[[#This Row],[Name]]="","", _xlfn.RANK.EQ(tblHelmet[[#This Row],[Score]], tblHelmet[Score], 0)) -> 17
A9: 加伦之恩典头冠 | B9: GARREN'S CROWN OF GRACE | C9: 鹿 | D9: 2 | E9: 2 | F9: 3 | H9: 1 | I9: 2 | K9: 2 | L9: 1 | N9: 1 | O9: 2 | R9: 15 | S9: =IF(tblHelmet[[#This Row],[Name]]="","", IF( AND( Sheet1!$A$2 >= tblHelmet[[#This Row],[min_cor]], Sheet1!$B$2 >= tblHelmet[[#This Row],[min_spi]], Sheet1!$C$2 >= tblHelmet[[#This Row],[min_gra]] ), _xlfn.FLOOR.MATH( value*tblHelmet[[#This Row],[phy_cor]]*Sheet1!$A$2 + value*tblHelmet[[#This Row],[phy_spi]]*Sheet1!$B$2 + value*tblHelmet[[#This Row],[phy_gra]]*Sheet1!$C$2 ) + tblHelmet[[#This Row],[Base_phy]], tblHelmet[[#This Row],[Base_phy]] )) -> 11 | T9: =IF(tblHelmet[[#This Row],[Name]]="","", IF(AND(Sheet1!$A$2>=tblHelmet[[#This Row],[min_cor]], Sheet1!$B$2>=tblHelmet[[#This Row],[min_spi]], Sheet1!$C$2>=tblHelmet[[#This Row],[min_gra]]), _xlfn.FLOOR.MATH(value*tblHelmet[[#This Row],[mag_cor]]*Sheet1!$A$2 + value*tblHelmet[[#This Row],[mag_spi]]*Sheet1!$B$2 + value*tblHelmet[[#This Row],[mag_gra]]*Sheet1!$C$2) + tblHelmet[[#This Row],[Base_mag]], tblHelmet[[#This Row],[Base_mag]])) -> 8 | U9: =IF(tblHelmet[[#This Row],[Name]]="","", IF(AND(Sheet1!$A$2>=tblHelmet[[#This Row],[min_cor]], Sheet1!$B$2>=tblHelmet[[#This Row],[min_spi]], Sheet1!$C$2>=tblHelmet[[#This Row],[min_gra]]), _xlfn.FLOOR.MATH(value*tblHelmet[[#This Row],[sta_cor]]*Sheet1!$A$2 + value*tblHelmet[[#This Row],[sta_spi]]*Sheet1!$B$2 + value*tblHelmet[[#This Row],[sta_gra]]*Sheet1!$C$2) + tblHelmet[[#This Row],[Base_sta]], tblHelmet[[#This Row],[Base_sta]])) -> 12 | V9: =IF(tblHelmet[[#This Row],[Name]]="","", tblHelmet[[#This Row],[phy]]*Sheet1!$E$2 + tblHelmet[[#This Row],[mag]]*Sheet1!$F$2 + tblHelmet[[#This Row],[sta]]*Sheet1!$G$2) -> 31 | W9: =IF(tblHelmet[[#This Row],[Name]]="","", _xlfn.RANK.EQ(tblHelmet[[#This Row],[Score]], tblHelmet[Score], 0)) -> 3
A10: 烈火之王头盔 | B10: GREAT HELM OF THE FIRE KING | C10: 集团 | D10: 3 | E10: 2 | F10: 2 | G10: 2 | I10: 2 | J10: 1 | M10: 1 | O10: 2 | P10: 15 | S10: =IF(tblHelmet[[#This Row],[Name]]="","", IF( AND( Sheet1!$A$2 >= tblHelmet[[#This Row],[min_cor]], Sheet1!$B$2 >= tblHelmet[[#This Row],[min_spi]], Sheet1!$C$2 >= tblHelmet[[#This Row],[min_gra]] ), _xlfn.FLOOR.MATH( value*tblHelmet[[#This Row],[phy_cor]]*Sheet1!$A$2 + value*tblHelmet[[#This Row],[phy_spi]]*Sheet1!$B$2 + value*tblHelmet[[#This Row],[phy_gra]]*Sheet1!$C$2 ) + tblHelmet[[#This Row],[Base_phy]], tblHelmet[[#This Row],[Base_phy]] )) -> 3 | T10: =IF(tblHelmet[[#This Row],[Name]]="","", IF(AND(Sheet1!$A$2>=tblHelmet[[#This Row],[min_cor]], Sheet1!$B$2>=tblHelmet[[#This Row],[min_spi]], Sheet1!$C$2>=tblHelmet[[#This Row],[min_gra]]), _xlfn.FLOOR.MATH(value*tblHelmet[[#This Row],[mag_cor]]*Sheet1!$A$2 + value*tblHelmet[[#This Row],[mag_spi]]*Sheet1!$B$2 + value*tblHelmet[[#This Row],[mag_gra]]*Sheet1!$C$2) + tblHelmet[[#This Row],[Base_mag]], tblHelmet[[#This Row],[Base_mag]])) -> 2 | U10: =IF(tblHelmet[[#This Row],[Name]]="","", IF(AND(Sheet1!$A$2>=tblHelmet[[#This Row],[min_cor]], Sheet1!$B$2>=tblHelmet[[#This Row],[min_spi]], Sheet1!$C$2>=tblHelmet[[#This Row],[min_gra]]), _xlfn.FLOOR.MATH(value*tblHelmet[[#This Row],[sta_cor]]*Sheet1!$A$2 + value*tblHelmet[[#This Row],[sta_spi]]*Sheet1!$B$2 + value*tblHelmet[[#This Row],[sta_gra]]*Sheet1!$C$2) + tblHelmet[[#This Row],[Base_sta]], tblHelmet[[#This Row],[Base_sta]])) -> 2 | V10: =IF(tblHelmet[[#This Row],[Name]]="","", tblHelmet[[#This Row],[phy]]*Sheet1!$E$2 + tblHelmet[[#This Row],[mag]]*Sheet1!$F$2 + tblHelmet[[#This Row],[sta]]*Sheet1!$G$2) -> 7 | W10: =IF(tblHelmet[[#This Row],[Name]]="","", _xlfn.RANK.EQ(tblHelmet[[#This Row],[Score]], tblHelmet[Score], 0)) -> 9
A11: 无头盔 | B11: HELMLESS | C11: 初始 | D11: 0 | E11: 0 | F11: 0 | S11: =IF(tblHelmet[[#This Row],[Name]]="","", IF( AND( Sheet1!$A$2 >= tblHelmet[[#This Row],[min_cor]], Sheet1!$B$2 >= tblHelmet[[#This Row],[min_spi]], Sheet1!$C$2 >= tblHelmet[[#This Row],[min_gra]] ), _xlfn.FLOOR.MATH( value*tblHelmet[[#This Row],[phy_cor]]*Sheet1!$A$2 + value*tblHelmet[[#This Row],[phy_spi]]*Sheet1!$B$2 + value*tblHelmet[[#This Row],[phy_gra]]*Sheet1!$C$2 ) + tblHelmet[[#This Row],[Base_phy]], tblHelmet[[#This Row],[Base_phy]] )) -> 0 | T11: =IF(tblHelmet[[#This Row],[Name]]="","", IF(AND(Sheet1!$A$2>=tblHelmet[[#This Row],[min_cor]], Sheet1!$B$2>=tblHelmet[[#This Row],[min_spi]], Sheet1!$C$2>=tblHelmet[[#This Row],[min_gra]]), _xlfn.FLOOR.MATH(value*tblHelmet[[#This Row],[mag_cor]]*Sheet1!$A$2 + value*tblHelmet[[#This Row],[mag_spi]]*Sheet1!$B$2 + value*tblHelmet[[#This Row],[mag_gra]]*Sheet1!$C$2) + tblHelmet[[#This Row],[Base_mag]], tblHelmet[[#This Row],[Base_mag]])) -> 0 | U11: =IF(tblHelmet[[#This Row],[Name]]="","", IF(AND(Sheet1!$A$2>=tblHelmet[[#This Row],[min_cor]], Sheet1!$B$2>=tblHelmet[[#This Row],[min_spi]], Sheet1!$C$2>=tblHelmet[[#This Row],[min_gra]]), _xlfn.FLOOR.MATH(value*tblHelmet[[#This Row],[sta_cor]]*Sheet1!$A$2 + value*tblHelmet[[#This Row],[sta_spi]]*Sheet1!$B$2 + value*tblHelmet[[#This Row],[sta_gra]]*Sheet1!$C$2) + tblHelmet[[#This Row],[Base_sta]], tblHelmet[[#This Row],[Base_sta]])) -> 0 | V11: =IF(tblHelmet[[#This Row],[Name]]="","", tblHelmet[[#This Row],[phy]]*Sheet1!$E$2 + tblHelmet[[#This Row],[mag]]*Sheet1!$F$2 + tblHelmet[[#This Row],[sta]]*Sheet1!$G$2) -> 0 | W11: =IF(tblHelmet[[#This Row],[Name]]="","", _xlfn.RANK.EQ(tblHelmet[[#This Row],[Score]], tblHelmet[Score], 0)) -> 25
A12: ！Lil'Zook面具 | B12: LIL' ZOOK MASK | C12: 某个节日 | D12: 4 | E12: 1 | F12: 2 | G12: 2 | H12: 2 | J12: 1 | K12: 2 | M12: 2 | P12: 12 | S12: =IF(tblHelmet[[#This Row],[Name]]="","", IF( AND( Sheet1!$A$2 >= tblHelmet[[#This Row],[min_cor]], Sheet1!$B$2 >= tblHelmet[[#This Row],[min_spi]], Sheet1!$C$2 >= tblHelmet[[#This Row],[min_gra]] ), _xlfn.FLOOR.MATH( value*tblHelmet[[#This Row],[phy_cor]]*Sheet1!$A$2 + value*tblHelmet[[#This Row],[phy_spi]]*Sheet1!$B$2 + value*tblHelmet[[#This Row],[phy_gra]]*Sheet1!$C$2 ) + tblHelmet[[#This Row],[Base_phy]], tblHelmet[[#This Row],[Base_phy]] )) -> 4 | T12: =IF(tblHelmet[[#This Row],[Name]]="","", IF(AND(Sheet1!$A$2>=tblHelmet[[#This Row],[min_cor]], Sheet1!$B$2>=tblHelmet[[#This Row],[min_spi]], Sheet1!$C$2>=tblHelmet[[#This Row],[min_gra]]), _xlfn.FLOOR.MATH(value*tblHelmet[[#This Row],[mag_cor]]*Sheet1!$A$2 + value*tblHelmet[[#This Row],[mag_spi]]*Sheet1!$B$2 + value*tblHelmet[[#This Row],[mag_gra]]*Sheet1!$C$2) + tblHelmet[[#This Row],[Base_mag]], tblHelmet[[#This Row],[Base_mag]])) -> 1 | U12: =IF(tblHelmet[[#This Row],[Name]]="","", IF(AND(Sheet1!$A$2>=tblHelmet[[#This Row],[min_cor]], Sheet1!$B$2>=tblHelmet[[#This Row],[min_spi]], Sheet1!$C$2>=tblHelmet[[#This Row],[min_gra]]), _xlfn.FLOOR.MATH(value*tblHelmet[[#This Row],[sta_cor]]*Sheet1!$A$2 + value*tblHelmet[[#This Row],[sta_spi]]*Sheet1!$B$2 + value*tblHelmet[[#This Row],[sta_gra]]*Sheet1!$C$2) + tblHelmet[[#This Row],[Base_sta]], tblHelmet[[#This Row],[Base_sta]])) -> 2 | V12: =IF(tblHelmet[[#This Row],[Name]]="","", tblHelmet[[#This Row],[phy]]*Sheet1!$E$2 + tblHelmet[[#This Row],[mag]]*Sheet1!$F$2 + tblHelmet[[#This Row],[sta]]*Sheet1!$G$2) -> 7 | W12: =IF(tblHelmet[[#This Row],[Name]]="","", _xlfn.RANK.EQ(tblHelmet[[#This Row],[Score]], tblHelmet[Score], 0)) -> 9
A13: 嘲魂盔帽 | B13: MOCKERY ILK | C13: 三重 | D13: 3 | E13: 3 | F13: 2 | H13: 2 | I13: 1 | K13: 2 | L13: 1 | N13: 1 | O13: 2 | R13: 20 | S13: =IF(tblHelmet[[#This Row],[Name]]="","", IF( AND( Sheet1!$A$2 >= tblHelmet[[#This Row],[min_cor]], Sheet1!$B$2 >= tblHelmet[[#This Row],[min_spi]], Sheet1!$C$2 >= tblHelmet[[#This Row],[min_gra]] ), _xlfn.FLOOR.MATH( value*tblHelmet[[#This Row],[phy_cor]]*Sheet1!$A$2 + value*tblHelmet[[#This Row],[phy_spi]]*Sheet1!$B$2 + value*tblHelmet[[#This Row],[phy_gra]]*Sheet1!$C$2 ) + tblHelmet[[#This Row],[Base_phy]], tblHelmet[[#This Row],[Base_phy]] )) -> 9 | T13: =IF(tblHelmet[[#This Row],[Name]]="","", IF(AND(Sheet1!$A$2>=tblHelmet[[#This Row],[min_cor]], Sheet1!$B$2>=tblHelmet[[#This Row],[min_spi]], Sheet1!$C$2>=tblHelmet[[#This Row],[min_gra]]), _xlfn.FLOOR.MATH(value*tblHelmet[[#This Row],[mag_cor]]*Sheet1!$A$2 + value*tblHelmet[[#This Row],[mag_spi]]*Sheet1!$B$2 + value*tblHelmet[[#This Row],[mag_gra]]*Sheet1!$C$2) + tblHelmet[[#This Row],[Base_mag]], tblHelmet[[#This Row],[Base_mag]])) -> 9 | U13: =IF(tblHelmet[[#This Row],[Name]]="","", IF(AND(Sheet1!$A$2>=tblHelmet[[#This Row],[min_cor]], Sheet1!$B$2>=tblHelmet[[#This Row],[min_spi]], Sheet1!$C$2>=tblHelmet[[#This Row],[min_gra]]), _xlfn.FLOOR.MATH(value*tblHelmet[[#This Row],[sta_cor]]*Sheet1!$A$2 + value*tblHelmet[[#This Row],[sta_spi]]*Sheet1!$B$2 + value*tblHelmet[[#This Row],[sta_gra]]*Sheet1!$C$2) + tblHelmet[[#This Row],[Base_sta]], tblHelmet[[#This Row],[Base_sta]])) -> 11 | V13: =IF(tblHelmet[[#This Row],[Name]]="","", tblHelmet[[#This Row],[phy]]*Sheet1!$E$2 + tblHelmet[[#This Row],[mag]]*Sheet1!$F$2 + tblHelmet[[#This Row],[sta]]*Sheet1!$G$2) -> 29 | W13: =IF(tblHelmet[[#This Row],[Name]]="","", _xlfn.RANK.EQ(tblHelmet[[#This Row],[Score]], tblHelmet[Score], 0)) -> 4
A14: 奥瑟达王冠 | B14: OSCELDA'S DIADEM | C14: 绿手初始 | D14: 1 | E14: 3 | F14: 0 | K14: 1 | S14: =IF(tblHelmet[[#This Row],[Name]]="","", IF( AND( Sheet1!$A$2 >= tblHelmet[[#This Row],[min_cor]], Sheet1!$B$2 >= tblHelmet[[#This Row],[min_spi]], Sheet1!$C$2 >= tblHelmet[[#This Row],[min_gra]] ), _xlfn.FLOOR.MATH( value*tblHelmet[[#This Row],[phy_cor]]*Sheet1!$A$2 + value*tblHelmet[[#This Row],[phy_spi]]*Sheet1!$B$2 + value*tblHelmet[[#This Row],[phy_gra]]*Sheet1!$C$2 ) + tblHelmet[[#This Row],[Base_phy]], tblHelmet[[#This Row],[Base_phy]] )) -> 1 | T14: =IF(tblHelmet[[#This Row],[Name]]="","", IF(AND(Sheet1!$A$2>=tblHelmet[[#This Row],[min_cor]], Sheet1!$B$2>=tblHelmet[[#This Row],[min_spi]], Sheet1!$C$2>=tblHelmet[[#This Row],[min_gra]]), _xlfn.FLOOR.MATH(value*tblHelmet[[#This Row],[mag_cor]]*Sheet1!$A$2 + value*tblHelmet[[#This Row],[mag_spi]]*Sheet1!$B$2 + value*tblHelmet[[#This Row],[mag_gra]]*Sheet1!$C$2) + tblHelmet[[#This Row],[Base_mag]], tblHelmet[[#This Row],[Base_mag]])) -> 3 | U14: =IF(tblHelmet[[#This Row],[Name]]="","", IF(AND(Sheet1!$A$2>=tblHelmet[[#This Row],[min_cor]], Sheet1!$B$2>=tblHelmet[[#This Row],[min_spi]], Sheet1!$C$2>=tblHelmet[[#This Row],[min_gra]]), _xlfn.FLOOR.MATH(value*tblHelmet[[#This Row],[sta_cor]]*Sheet1!$A$2 + value*tblHelmet[[#This Row],[sta_spi]]*Sheet1!$B$2 + value*tblHelmet[[#This Row],[sta_gra]]*Sheet1!$C$2) + tblHelmet[[#This Row],[Base_sta]], tblHelmet[[#This Row],[Base_sta]])) -> 0 | V14: =IF(tblHelmet[[#This Row],[Name]]="","", tblHelmet[[#This Row],[phy]]*Sheet1!$E$2 + tblHelmet[[#This Row],[mag]]*Sheet1!$F$2 + tblHelmet[[#This Row],[sta]]*Sheet1!$G$2) -> 4 | W14: =IF(tblHelmet[[#This Row],[Name]]="","", _xlfn.RANK.EQ(tblHelmet[[#This Row],[Score]], tblHelmet[Score], 0)) -> 24
A15: ！Poppa Pepo面具 | B15: POPPA PEPO MASK | C15: 某个节日 | D15: 2 | E15: 2 | F15: 6 | I15: 1 | K15: 2 | L15: 2 | N15: 2 | O15: 2 | R15: 12 | S15: =IF(tblHelmet[[#This Row],[Name]]="","", IF( AND( Sheet1!$A$2 >= tblHelmet[[#This Row],[min_cor]], Sheet1!$B$2 >= tblHelmet[[#This Row],[min_spi]], Sheet1!$C$2 >= tblHelmet[[#This Row],[min_gra]] ), _xlfn.FLOOR.MATH( value*tblHelmet[[#This Row],[phy_cor]]*Sheet1!$A$2 + value*tblHelmet[[#This Row],[phy_spi]]*Sheet1!$B$2 + value*tblHelmet[[#This Row],[phy_gra]]*Sheet1!$C$2 ) + tblHelmet[[#This Row],[Base_phy]], tblHelmet[[#This Row],[Base_phy]] )) -> 6 | T15: =IF(tblHelmet[[#This Row],[Name]]="","", IF(AND(Sheet1!$A$2>=tblHelmet[[#This Row],[min_cor]], Sheet1!$B$2>=tblHelmet[[#This Row],[min_spi]], Sheet1!$C$2>=tblHelmet[[#This Row],[min_gra]]), _xlfn.FLOOR.MATH(value*tblHelmet[[#This Row],[mag_cor]]*Sheet1!$A$2 + value*tblHelmet[[#This Row],[mag_spi]]*Sheet1!$B$2 + value*tblHelmet[[#This Row],[mag_gra]]*Sheet1!$C$2) + tblHelmet[[#This Row],[Base_mag]], tblHelmet[[#This Row],[Base_mag]])) -> 12 | U15: =IF(tblHelmet[[#This Row],[Name]]="","", IF(AND(Sheet1!$A$2>=tblHelmet[[#This Row],[min_cor]], Sheet1!$B$2>=tblHelmet[[#This Row],[min_spi]], Sheet1!$C$2>=tblHelmet[[#This Row],[min_gra]]), _xlfn.FLOOR.MATH(value*tblHelmet[[#This Row],[sta_cor]]*Sheet1!$A$2 + value*tblHelmet[[#This Row],[sta_spi]]*Sheet1!$B$2 + value*tblHelmet[[#This Row],[sta_gra]]*Sheet1!$C$2) + tblHelmet[[#This Row],[Base_sta]], tblHelmet[[#This Row],[Base_sta]])) -> 16 | V15: =IF(tblHelmet[[#This Row],[Name]]="","", tblHelmet[[#This Row],[phy]]*Sheet1!$E$2 + tblHelmet[[#This Row],[mag]]*Sheet1!$F$2 + tblHelmet[[#This Row],[sta]]*Sheet1!$G$2) -> 34 | W15: =IF(tblHelmet[[#This Row],[Name]]="","", _xlfn.RANK.EQ(tblHelmet[[#This Row],[Score]], tblHelmet[Score], 0)) -> 2
A16: 摄政头巾 | B16: REGENT'S VEIL | C16: 集团 | D16: 3 | E16: 1 | F16: 1 | G16: 2 | H16: 2 | J16: 1 | K16: 2 | M16: 2 | P16: 15 | S16: =IF(tblHelmet[[#This Row],[Name]]="","", IF( AND( Sheet1!$A$2 >= tblHelmet[[#This Row],[min_cor]], Sheet1!$B$2 >= tblHelmet[[#This Row],[min_spi]], Sheet1!$C$2 >= tblHelmet[[#This Row],[min_gra]] ), _xlfn.FLOOR.MATH( value*tblHelmet[[#This Row],[phy_cor]]*Sheet1!$A$2 + value*tblHelmet[[#This Row],[phy_spi]]*Sheet1!$B$2 + value*tblHelmet[[#This Row],[phy_gra]]*Sheet1!$C$2 ) + tblHelmet[[#This Row],[Base_phy]], tblHelmet[[#This Row],[Base_phy]] )) -> 3 | T16: =IF(tblHelmet[[#This Row],[Name]]="","", IF(AND(Sheet1!$A$2>=tblHelmet[[#This Row],[min_cor]], Sheet1!$B$2>=tblHelmet[[#This Row],[min_spi]], Sheet1!$C$2>=tblHelmet[[#This Row],[min_gra]]), _xlfn.FLOOR.MATH(value*tblHelmet[[#This Row],[mag_cor]]*Sheet1!$A$2 + value*tblHelmet[[#This Row],[mag_spi]]*Sheet1!$B$2 + value*tblHelmet[[#This Row],[mag_gra]]*Sheet1!$C$2) + tblHelmet[[#This Row],[Base_mag]], tblHelmet[[#This Row],[Base_mag]])) -> 1 | U16: =IF(tblHelmet[[#This Row],[Name]]="","", IF(AND(Sheet1!$A$2>=tblHelmet[[#This Row],[min_cor]], Sheet1!$B$2>=tblHelmet[[#This Row],[min_spi]], Sheet1!$C$2>=tblHelmet[[#This Row],[min_gra]]), _xlfn.FLOOR.MATH(value*tblHelmet[[#This Row],[sta_cor]]*Sheet1!$A$2 + value*tblHelmet[[#This Row],[sta_spi]]*Sheet1!$B$2 + value*tblHelmet[[#This Row],[sta_gra]]*Sheet1!$C$2) + tblHelmet[[#This Row],[Base_sta]], tblHelmet[[#This Row],[Base_sta]])) -> 1 | V16: =IF(tblHelmet[[#This Row],[Name]]="","", tblHelmet[[#This Row],[phy]]*Sheet1!$E$2 + tblHelmet[[#This Row],[mag]]*Sheet1!$F$2 + tblHelmet[[#This Row],[sta]]*Sheet1!$G$2) -> 5 | W16: =IF(tblHelmet[[#This Row],[Name]]="","", _xlfn.RANK.EQ(tblHelmet[[#This Row],[Score]], tblHelmet[Score], 0)) -> 20
A17: 西林兜帽 | B17: SIRIN'S SHROUD | C17: 蓝手初始 | D17: 2 | E17: 0 | F17: 3 | O17: 1 | S17: =IF(tblHelmet[[#This Row],[Name]]="","", IF( AND( Sheet1!$A$2 >= tblHelmet[[#This Row],[min_cor]], Sheet1!$B$2 >= tblHelmet[[#This Row],[min_spi]], Sheet1!$C$2 >= tblHelmet[[#This Row],[min_gra]] ), _xlfn.FLOOR.MATH( value*tblHelmet[[#This Row],[phy_cor]]*Sheet1!$A$2 + value*tblHelmet[[#This Row],[phy_spi]]*Sheet1!$B$2 + value*tblHelmet[[#This Row],[phy_gra]]*Sheet1!$C$2 ) + tblHelmet[[#This Row],[Base_phy]], tblHelmet[[#This Row],[Base_phy]] )) -> 2 | T17: =IF(tblHelmet[[#This Row],[Name]]="","", IF(AND(Sheet1!$A$2>=tblHelmet[[#This Row],[min_cor]], Sheet1!$B$2>=tblHelmet[[#This Row],[min_spi]], Sheet1!$C$2>=tblHelmet[[#This Row],[min_gra]]), _xlfn.FLOOR.MATH(value*tblHelmet[[#This Row],[mag_cor]]*Sheet1!$A$2 + value*tblHelmet[[#This Row],[mag_spi]]*Sheet1!$B$2 + value*tblHelmet[[#This Row],[mag_gra]]*Sheet1!$C$2) + tblHelmet[[#This Row],[Base_mag]], tblHelmet[[#This Row],[Base_mag]])) -> 0 | U17: =IF(tblHelmet[[#This Row],[Name]]="","", IF(AND(Sheet1!$A$2>=tblHelmet[[#This Row],[min_cor]], Sheet1!$B$2>=tblHelmet[[#This Row],[min_spi]], Sheet1!$C$2>=tblHelmet[[#This Row],[min_gra]]), _xlfn.FLOOR.MATH(value*tblHelmet[[#This Row],[sta_cor]]*Sheet1!$A$2 + value*tblHelmet[[#This Row],[sta_spi]]*Sheet1!$B$2 + value*tblHelmet[[#This Row],[sta_gra]]*Sheet1!$C$2) + tblHelmet[[#This Row],[Base_sta]], tblHelmet[[#This Row],[Base_sta]])) -> 7 | V17: =IF(tblHelmet[[#This Row],[Name]]="","", tblHelmet[[#This Row],[phy]]*Sheet1!$E$2 + tblHelmet[[#This Row],[mag]]*Sheet1!$F$2 + tblHelmet[[#This Row],[sta]]*Sheet1!$G$2) -> 9 | W17: =IF(tblHelmet[[#This Row],[Name]]="","", _xlfn.RANK.EQ(tblHelmet[[#This Row],[Score]], tblHelmet[Score], 0)) -> 8
A18: 钢咏师头环 | B18: STEELSINGER'S CIRCLET | C18: 双轨炮 | D18: 2 | E18: 2 | F18: 1 | H18: 2 | K18: 2 | N18: 2 | Q18: 14 | S18: =IF(tblHelmet[[#This Row],[Name]]="","", IF( AND( Sheet1!$A$2 >= tblHelmet[[#This Row],[min_cor]], Sheet1!$B$2 >= tblHelmet[[#This Row],[min_spi]], Sheet1!$C$2 >= tblHelmet[[#This Row],[min_gra]] ), _xlfn.FLOOR.MATH( value*tblHelmet[[#This Row],[phy_cor]]*Sheet1!$A$2 + value*tblHelmet[[#This Row],[phy_spi]]*Sheet1!$B$2 + value*tblHelmet[[#This Row],[phy_gra]]*Sheet1!$C$2 ) + tblHelmet[[#This Row],[Base_phy]], tblHelmet[[#This Row],[Base_phy]] )) -> 2 | T18: =IF(tblHelmet[[#This Row],[Name]]="","", IF(AND(Sheet1!$A$2>=tblHelmet[[#This Row],[min_cor]], Sheet1!$B$2>=tblHelmet[[#This Row],[min_spi]], Sheet1!$C$2>=tblHelmet[[#This Row],[min_gra]]), _xlfn.FLOOR.MATH(value*tblHelmet[[#This Row],[mag_cor]]*Sheet1!$A$2 + value*tblHelmet[[#This Row],[mag_spi]]*Sheet1!$B$2 + value*tblHelmet[[#This Row],[mag_gra]]*Sheet1!$C$2) + tblHelmet[[#This Row],[Base_mag]], tblHelmet[[#This Row],[Base_mag]])) -> 2 | U18: =IF(tblHelmet[[#This Row],[Name]]="","", IF(AND(Sheet1!$A$2>=tblHelmet[[#This Row],[min_cor]], Sheet1!$B$2>=tblHelmet[[#This Row],[min_spi]], Sheet1!$C$2>=tblHelmet[[#This Row],[min_gra]]), _xlfn.FLOOR.MATH(value*tblHelmet[[#This Row],[sta_cor]]*Sheet1!$A$2 + value*tblHelmet[[#This Row],[sta_spi]]*Sheet1!$B$2 + value*tblHelmet[[#This Row],[sta_gra]]*Sheet1!$C$2) + tblHelmet[[#This Row],[Base_sta]], tblHelmet[[#This Row],[Base_sta]])) -> 1 | V18: =IF(tblHelmet[[#This Row],[Name]]="","", tblHelmet[[#This Row],[phy]]*Sheet1!$E$2 + tblHelmet[[#This Row],[mag]]*Sheet1!$F$2 + tblHelmet[[#This Row],[sta]]*Sheet1!$G$2) -> 5 | W18: =IF(tblHelmet[[#This Row],[Name]]="","", _xlfn.RANK.EQ(tblHelmet[[#This Row],[Score]], tblHelmet[Score], 0)) -> 20
A19: 暴风面罩 | B19: TEMPEST VISARD | C19: 集团 | D19: 3 | E19: 0 | F19: 3 | I19: 2 | O19: 2 | R19: 10 | S19: =IF(tblHelmet[[#This Row],[Name]]="","", IF( AND( Sheet1!$A$2 >= tblHelmet[[#This Row],[min_cor]], Sheet1!$B$2 >= tblHelmet[[#This Row],[min_spi]], Sheet1!$C$2 >= tblHelmet[[#This Row],[min_gra]] ), _xlfn.FLOOR.MATH( value*tblHelmet[[#This Row],[phy_cor]]*Sheet1!$A$2 + value*tblHelmet[[#This Row],[phy_spi]]*Sheet1!$B$2 + value*tblHelmet[[#This Row],[phy_gra]]*Sheet1!$C$2 ) + tblHelmet[[#This Row],[Base_phy]], tblHelmet[[#This Row],[Base_phy]] )) -> 12 | T19: =IF(tblHelmet[[#This Row],[Name]]="","", IF(AND(Sheet1!$A$2>=tblHelmet[[#This Row],[min_cor]], Sheet1!$B$2>=tblHelmet[[#This Row],[min_spi]], Sheet1!$C$2>=tblHelmet[[#This Row],[min_gra]]), _xlfn.FLOOR.MATH(value*tblHelmet[[#This Row],[mag_cor]]*Sheet1!$A$2 + value*tblHelmet[[#This Row],[mag_spi]]*Sheet1!$B$2 + value*tblHelmet[[#This Row],[mag_gra]]*Sheet1!$C$2) + tblHelmet[[#This Row],[Base_mag]], tblHelmet[[#This Row],[Base_mag]])) -> 0 | U19: =IF(tblHelmet[[#This Row],[Name]]="","", IF(AND(Sheet1!$A$2>=tblHelmet[[#This Row],[min_cor]], Sheet1!$B$2>=tblHelmet[[#This Row],[min_spi]], Sheet1!$C$2>=tblHelmet[[#This Row],[min_gra]]), _xlfn.FLOOR.MATH(value*tblHelmet[[#This Row],[sta_cor]]*Sheet1!$A$2 + value*tblHelmet[[#This Row],[sta_spi]]*Sheet1!$B$2 + value*tblHelmet[[#This Row],[sta_gra]]*Sheet1!$C$2) + tblHelmet[[#This Row],[Base_sta]], tblHelmet[[#This Row],[Base_sta]])) -> 12 | V19: =IF(tblHelmet[[#This Row],[Name]]="","", tblHelmet[[#This Row],[phy]]*Sheet1!$E$2 + tblHelmet[[#This Row],[mag]]*Sheet1!$F$2 + tblHelmet[[#This Row],[sta]]*Sheet1!$G$2) -> 24 | W19: =IF(tblHelmet[[#This Row],[Name]]="","", _xlfn.RANK.EQ(tblHelmet[[#This Row],[Score]], tblHelmet[Score], 0)) -> 6
A20: 特斯伦帽 | B20: TETHREN'S CAP | C20: 红手初始 | D20: 3 | E20: 0 | F20: 2 | G20: 1 | S20: =IF(tblHelmet[[#This Row],[Name]]="","", IF( AND( Sheet1!$A$2 >= tblHelmet[[#This Row],[min_cor]], Sheet1!$B$2 >= tblHelmet[[#This Row],[min_spi]], Sheet1!$C$2 >= tblHelmet[[#This Row],[min_gra]] ), _xlfn.FLOOR.MATH( value*tblHelmet[[#This Row],[phy_cor]]*Sheet1!$A$2 + value*tblHelmet[[#This Row],[phy_spi]]*Sheet1!$B$2 + value*tblHelmet[[#This Row],[phy_gra]]*Sheet1!$C$2 ) + tblHelmet[[#This Row],[Base_phy]], tblHelmet[[#This Row],[Base_phy]] )) -> 3 | T20: =IF(tblHelmet[[#This Row],[Name]]="","", IF(AND(Sheet1!$A$2>=tblHelmet[[#This Row],[min_cor]], Sheet1!$B$2>=tblHelmet[[#This Row],[min_spi]], Sheet1!$C$2>=tblHelmet[[#This Row],[min_gra]]), _xlfn.FLOOR.MATH(value*tblHelmet[[#This Row],[mag_cor]]*Sheet1!$A$2 + value*tblHelmet[[#This Row],[mag_spi]]*Sheet1!$B$2 + value*tblHelmet[[#This Row],[mag_gra]]*Sheet1!$C$2) + tblHelmet[[#This Row],[Base_mag]], tblHelmet[[#This Row],[Base_mag]])) -> 0 | U20: =IF(tblHelmet[[#This Row],[Name]]="","", IF(AND(Sheet1!$A$2>=tblHelmet[[#This Row],[min_cor]], Sheet1!$B$2>=tblHelmet[[#This Row],[min_spi]], Sheet1!$C$2>=tblHelmet[[#This Row],[min_gra]]), _xlfn.FLOOR.MATH(value*tblHelmet[[#This Row],[sta_cor]]*Sheet1!$A$2 + value*tblHelmet[[#This Row],[sta_spi]]*Sheet1!$B$2 + value*tblHelmet[[#This Row],[sta_gra]]*Sheet1!$C$2) + tblHelmet[[#This Row],[Base_sta]], tblHelmet[[#This Row],[Base_sta]])) -> 2 | V20: =IF(tblHelmet[[#This Row],[Name]]="","", tblHelmet[[#This Row],[phy]]*Sheet1!$E$2 + tblHelmet[[#This Row],[mag]]*Sheet1!$F$2 + tblHelmet[[#This Row],[sta]]*Sheet1!$G$2) -> 5 | W20: =IF(tblHelmet[[#This Row],[Name]]="","", _xlfn.RANK.EQ(tblHelmet[[#This Row],[Score]], tblHelmet[Score], 0)) -> 20
A21: 雪融黯面 | B21: THAWTIDE GRIMGUISE | C21: 雪融节 | D21: 4 | E21: 2 | F21: 1 | G21: 2 | J21: 2 | M21: 2 | P21: 16 | S21: =IF(tblHelmet[[#This Row],[Name]]="","", IF( AND( Sheet1!$A$2 >= tblHelmet[[#This Row],[min_cor]], Sheet1!$B$2 >= tblHelmet[[#This Row],[min_spi]], Sheet1!$C$2 >= tblHelmet[[#This Row],[min_gra]] ), _xlfn.FLOOR.MATH( value*tblHelmet[[#This Row],[phy_cor]]*Sheet1!$A$2 + value*tblHelmet[[#This Row],[phy_spi]]*Sheet1!$B$2 + value*tblHelmet[[#This Row],[phy_gra]]*Sheet1!$C$2 ) + tblHelmet[[#This Row],[Base_phy]], tblHelmet[[#This Row],[Base_phy]] )) -> 4 | T21: =IF(tblHelmet[[#This Row],[Name]]="","", IF(AND(Sheet1!$A$2>=tblHelmet[[#This Row],[min_cor]], Sheet1!$B$2>=tblHelmet[[#This Row],[min_spi]], Sheet1!$C$2>=tblHelmet[[#This Row],[min_gra]]), _xlfn.FLOOR.MATH(value*tblHelmet[[#This Row],[mag_cor]]*Sheet1!$A$2 + value*tblHelmet[[#This Row],[mag_spi]]*Sheet1!$B$2 + value*tblHelmet[[#This Row],[mag_gra]]*Sheet1!$C$2) + tblHelmet[[#This Row],[Base_mag]], tblHelmet[[#This Row],[Base_mag]])) -> 2 | U21: =IF(tblHelmet[[#This Row],[Name]]="","", IF(AND(Sheet1!$A$2>=tblHelmet[[#This Row],[min_cor]], Sheet1!$B$2>=tblHelmet[[#This Row],[min_spi]], Sheet1!$C$2>=tblHelmet[[#This Row],[min_gra]]), _xlfn.FLOOR.MATH(value*tblHelmet[[#This Row],[sta_cor]]*Sheet1!$A$2 + value*tblHelmet[[#This Row],[sta_spi]]*Sheet1!$B$2 + value*tblHelmet[[#This Row],[sta_gra]]*Sheet1!$C$2) + tblHelmet[[#This Row],[Base_sta]], tblHelmet[[#This Row],[Base_sta]])) -> 1 | V21: =IF(tblHelmet[[#This Row],[Name]]="","", tblHelmet[[#This Row],[phy]]*Sheet1!$E$2 + tblHelmet[[#This Row],[mag]]*Sheet1!$F$2 + tblHelmet[[#This Row],[sta]]*Sheet1!$G$2) -> 7 | W21: =IF(tblHelmet[[#This Row],[Name]]="","", _xlfn.RANK.EQ(tblHelmet[[#This Row],[Score]], tblHelmet[Score], 0)) -> 9
A22: 雪融蚀帽 | B22: THAWTIDE MELTCAP | C22: 雪融节 | D22: 3 | E22: 0 | F22: 2 | G22: 2 | I22: 2 | M22: 2 | O22: 2 | R22: 17 | S22: =IF(tblHelmet[[#This Row],[Name]]="","", IF( AND( Sheet1!$A$2 >= tblHelmet[[#This Row],[min_cor]], Sheet1!$B$2 >= tblHelmet[[#This Row],[min_spi]], Sheet1!$C$2 >= tblHelmet[[#This Row],[min_gra]] ), _xlfn.FLOOR.MATH( value*tblHelmet[[#This Row],[phy_cor]]*Sheet1!$A$2 + value*tblHelmet[[#This Row],[phy_spi]]*Sheet1!$B$2 + value*tblHelmet[[#This Row],[phy_gra]]*Sheet1!$C$2 ) + tblHelmet[[#This Row],[Base_phy]], tblHelmet[[#This Row],[Base_phy]] )) -> 14 | T22: =IF(tblHelmet[[#This Row],[Name]]="","", IF(AND(Sheet1!$A$2>=tblHelmet[[#This Row],[min_cor]], Sheet1!$B$2>=tblHelmet[[#This Row],[min_spi]], Sheet1!$C$2>=tblHelmet[[#This Row],[min_gra]]), _xlfn.FLOOR.MATH(value*tblHelmet[[#This Row],[mag_cor]]*Sheet1!$A$2 + value*tblHelmet[[#This Row],[mag_spi]]*Sheet1!$B$2 + value*tblHelmet[[#This Row],[mag_gra]]*Sheet1!$C$2) + tblHelmet[[#This Row],[Base_mag]], tblHelmet[[#This Row],[Base_mag]])) -> 0 | U22: =IF(tblHelmet[[#This Row],[Name]]="","", IF(AND(Sheet1!$A$2>=tblHelmet[[#This Row],[min_cor]], Sheet1!$B$2>=tblHelmet[[#This Row],[min_spi]], Sheet1!$C$2>=tblHelmet[[#This Row],[min_gra]]), _xlfn.FLOOR.MATH(value*tblHelmet[[#This Row],[sta_cor]]*Sheet1!$A$2 + value*tblHelmet[[#This Row],[sta_spi]]*Sheet1!$B$2 + value*tblHelmet[[#This Row],[sta_gra]]*Sheet1!$C$2) + tblHelmet[[#This Row],[Base_sta]], tblHelmet[[#This Row],[Base_sta]])) -> 13 | V22: =IF(tblHelmet[[#This Row],[Name]]="","", tblHelmet[[#This Row],[phy]]*Sheet1!$E$2 + tblHelmet[[#This Row],[mag]]*Sheet1!$F$2 + tblHelmet[[#This Row],[sta]]*Sheet1!$G$2) -> 27 | W22: =IF(tblHelmet[[#This Row],[Name]]="","", _xlfn.RANK.EQ(tblHelmet[[#This Row],[Score]], tblHelmet[Score], 0)) -> 5
A23: 巫术师的尖顶帽 | B23: WAZZARD'S BYCOKET | C23: 器管 | D23: 2 | E23: 3 | F23: 2 | H23: 2 | K23: 3 | N23: 1 | Q23: 22 | S23: =IF(tblHelmet[[#This Row],[Name]]="","", IF( AND( Sheet1!$A$2 >= tblHelmet[[#This Row],[min_cor]], Sheet1!$B$2 >= tblHelmet[[#This Row],[min_spi]], Sheet1!$C$2 >= tblHelmet[[#This Row],[min_gra]] ), _xlfn.FLOOR.MATH( value*tblHelmet[[#This Row],[phy_cor]]*Sheet1!$A$2 + value*tblHelmet[[#This Row],[phy_spi]]*Sheet1!$B$2 + value*tblHelmet[[#This Row],[phy_gra]]*Sheet1!$C$2 ) + tblHelmet[[#This Row],[Base_phy]], tblHelmet[[#This Row],[Base_phy]] )) -> 2 | T23: =IF(tblHelmet[[#This Row],[Name]]="","", IF(AND(Sheet1!$A$2>=tblHelmet[[#This Row],[min_cor]], Sheet1!$B$2>=tblHelmet[[#This Row],[min_spi]], Sheet1!$C$2>=tblHelmet[[#This Row],[min_gra]]), _xlfn.FLOOR.MATH(value*tblHelmet[[#This Row],[mag_cor]]*Sheet1!$A$2 + value*tblHelmet[[#This Row],[mag_spi]]*Sheet1!$B$2 + value*tblHelmet[[#This Row],[mag_gra]]*Sheet1!$C$2) + tblHelmet[[#This Row],[Base_mag]], tblHelmet[[#This Row],[Base_mag]])) -> 3 | U23: =IF(tblHelmet[[#This Row],[Name]]="","", IF(AND(Sheet1!$A$2>=tblHelmet[[#This Row],[min_cor]], Sheet1!$B$2>=tblHelmet[[#This Row],[min_spi]], Sheet1!$C$2>=tblHelmet[[#This Row],[min_gra]]), _xlfn.FLOOR.MATH(value*tblHelmet[[#This Row],[sta_cor]]*Sheet1!$A$2 + value*tblHelmet[[#This Row],[sta_spi]]*Sheet1!$B$2 + value*tblHelmet[[#This Row],[sta_gra]]*Sheet1!$C$2) + tblHelmet[[#This Row],[Base_sta]], tblHelmet[[#This Row],[Base_sta]])) -> 2 | V23: =IF(tblHelmet[[#This Row],[Name]]="","", tblHelmet[[#This Row],[phy]]*Sheet1!$E$2 + tblHelmet[[#This Row],[mag]]*Sheet1!$F$2 + tblHelmet[[#This Row],[sta]]*Sheet1!$G$2) -> 7 | W23: =IF(tblHelmet[[#This Row],[Name]]="","", _xlfn.RANK.EQ(tblHelmet[[#This Row],[Score]], tblHelmet[Score], 0)) -> 9
A24: 荒源奥瑟达赞歌头盔 | B24: WYLD OSCELDA'S EXHALT | C24: 绿手大包 | D24: 1 | E24: 3 | F24: 0 | H24: 2 | K24: 1 | S24: =IF(tblHelmet[[#This Row],[Name]]="","", IF( AND( Sheet1!$A$2 >= tblHelmet[[#This Row],[min_cor]], Sheet1!$B$2 >= tblHelmet[[#This Row],[min_spi]], Sheet1!$C$2 >= tblHelmet[[#This Row],[min_gra]] ), _xlfn.FLOOR.MATH( value*tblHelmet[[#This Row],[phy_cor]]*Sheet1!$A$2 + value*tblHelmet[[#This Row],[phy_spi]]*Sheet1!$B$2 + value*tblHelmet[[#This Row],[phy_gra]]*Sheet1!$C$2 ) + tblHelmet[[#This Row],[Base_phy]], tblHelmet[[#This Row],[Base_phy]] )) -> 2 | T24: =IF(tblHelmet[[#This Row],[Name]]="","", IF(AND(Sheet1!$A$2>=tblHelmet[[#This Row],[min_cor]], Sheet1!$B$2>=tblHelmet[[#This Row],[min_spi]], Sheet1!$C$2>=tblHelmet[[#This Row],[min_gra]]), _xlfn.FLOOR.MATH(value*tblHelmet[[#This Row],[mag_cor]]*Sheet1!$A$2 + value*tblHelmet[[#This Row],[mag_spi]]*Sheet1!$B$2 + value*tblHelmet[[#This Row],[mag_gra]]*Sheet1!$C$2) + tblHelmet[[#This Row],[Base_mag]], tblHelmet[[#This Row],[Base_mag]])) -> 3 | U24: =IF(tblHelmet[[#This Row],[Name]]="","", IF(AND(Sheet1!$A$2>=tblHelmet[[#This Row],[min_cor]], Sheet1!$B$2>=tblHelmet[[#This Row],[min_spi]], Sheet1!$C$2>=tblHelmet[[#This Row],[min_gra]]), _xlfn.FLOOR.MATH(value*tblHelmet[[#This Row],[sta_cor]]*Sheet1!$A$2 + value*tblHelmet[[#This Row],[sta_spi]]*Sheet1!$B$2 + value*tblHelmet[[#This Row],[sta_gra]]*Sheet1!$C$2) + tblHelmet[[#This Row],[Base_sta]], tblHelmet[[#This Row],[Base_sta]])) -> 0 | V24: =IF(tblHelmet[[#This Row],[Name]]="","", tblHelmet[[#This Row],[phy]]*Sheet1!$E$2 + tblHelmet[[#This Row],[mag]]*Sheet1!$F$2 + tblHelmet[[#This Row],[sta]]*Sheet1!$G$2) -> 5 | W24: =IF(tblHelmet[[#This Row],[Name]]="","", _xlfn.RANK.EQ(tblHelmet[[#This Row],[Score]], tblHelmet[Score], 0)) -> 20
A25: 荒源西林假面 | B25: WYLD SIRIN'S FEIGNMASK | C25: 蓝手大包 | D25: 2 | E25: 0 | F25: 3 | I25: 2 | O25: 1 | S25: =IF(tblHelmet[[#This Row],[Name]]="","", IF( AND( Sheet1!$A$2 >= tblHelmet[[#This Row],[min_cor]], Sheet1!$B$2 >= tblHelmet[[#This Row],[min_spi]], Sheet1!$C$2 >= tblHelmet[[#This Row],[min_gra]] ), _xlfn.FLOOR.MATH( value*tblHelmet[[#This Row],[phy_cor]]*Sheet1!$A$2 + value*tblHelmet[[#This Row],[phy_spi]]*Sheet1!$B$2 + value*tblHelmet[[#This Row],[phy_gra]]*Sheet1!$C$2 ) + tblHelmet[[#This Row],[Base_phy]], tblHelmet[[#This Row],[Base_phy]] )) -> 11 | T25: =IF(tblHelmet[[#This Row],[Name]]="","", IF(AND(Sheet1!$A$2>=tblHelmet[[#This Row],[min_cor]], Sheet1!$B$2>=tblHelmet[[#This Row],[min_spi]], Sheet1!$C$2>=tblHelmet[[#This Row],[min_gra]]), _xlfn.FLOOR.MATH(value*tblHelmet[[#This Row],[mag_cor]]*Sheet1!$A$2 + value*tblHelmet[[#This Row],[mag_spi]]*Sheet1!$B$2 + value*tblHelmet[[#This Row],[mag_gra]]*Sheet1!$C$2) + tblHelmet[[#This Row],[Base_mag]], tblHelmet[[#This Row],[Base_mag]])) -> 0 | U25: =IF(tblHelmet[[#This Row],[Name]]="","", IF(AND(Sheet1!$A$2>=tblHelmet[[#This Row],[min_cor]], Sheet1!$B$2>=tblHelmet[[#This Row],[min_spi]], Sheet1!$C$2>=tblHelmet[[#This Row],[min_gra]]), _xlfn.FLOOR.MATH(value*tblHelmet[[#This Row],[sta_cor]]*Sheet1!$A$2 + value*tblHelmet[[#This Row],[sta_spi]]*Sheet1!$B$2 + value*tblHelmet[[#This Row],[sta_gra]]*Sheet1!$C$2) + tblHelmet[[#This Row],[Base_sta]], tblHelmet[[#This Row],[Base_sta]])) -> 7 | V25: =IF(tblHelmet[[#This Row],[Name]]="","", tblHelmet[[#This Row],[phy]]*Sheet1!$E$2 + tblHelmet[[#This Row],[mag]]*Sheet1!$F$2 + tblHelmet[[#This Row],[sta]]*Sheet1!$G$2) -> 18 | W25: =IF(tblHelmet[[#This Row],[Name]]="","", _xlfn.RANK.EQ(tblHelmet[[#This Row],[Score]], tblHelmet[Score], 0)) -> 7
A26: 荒源特斯伦号角头盔 | B26: WYLD TETHREN'S HORNHELM | C26: 红手大包 | D26: 3 | E26: 0 | F26: 2 | G26: 2 | M26: 1 | S26: =IF(tblHelmet[[#This Row],[Name]]="","", IF( AND( Sheet1!$A$2 >= tblHelmet[[#This Row],[min_cor]], Sheet1!$B$2 >= tblHelmet[[#This Row],[min_spi]], Sheet1!$C$2 >= tblHelmet[[#This Row],[min_gra]] ), _xlfn.FLOOR.MATH( value*tblHelmet[[#This Row],[phy_cor]]*Sheet1!$A$2 + value*tblHelmet[[#This Row],[phy_spi]]*Sheet1!$B$2 + value*tblHelmet[[#This Row],[phy_gra]]*Sheet1!$C$2 ) + tblHelmet[[#This Row],[Base_phy]], tblHelmet[[#This Row],[Base_phy]] )) -> 4 | T26: =IF(tblHelmet[[#This Row],[Name]]="","", IF(AND(Sheet1!$A$2>=tblHelmet[[#This Row],[min_cor]], Sheet1!$B$2>=tblHelmet[[#This Row],[min_spi]], Sheet1!$C$2>=tblHelmet[[#This Row],[min_gra]]), _xlfn.FLOOR.MATH(value*tblHelmet[[#This Row],[mag_cor]]*Sheet1!$A$2 + value*tblHelmet[[#This Row],[mag_spi]]*Sheet1!$B$2 + value*tblHelmet[[#This Row],[mag_gra]]*Sheet1!$C$2) + tblHelmet[[#This Row],[Base_mag]], tblHelmet[[#This Row],[Base_mag]])) -> 0 | U26: =IF(tblHelmet[[#This Row],[Name]]="","", IF(AND(Sheet1!$A$2>=tblHelmet[[#This Row],[min_cor]], Sheet1!$B$2>=tblHelmet[[#This Row],[min_spi]], Sheet1!$C$2>=tblHelmet[[#This Row],[min_gra]]), _xlfn.FLOOR.MATH(value*tblHelmet[[#This Row],[sta_cor]]*Sheet1!$A$2 + value*tblHelmet[[#This Row],[sta_spi]]*Sheet1!$B$2 + value*tblHelmet[[#This Row],[sta_gra]]*Sheet1!$C$2) + tblHelmet[[#This Row],[Base_sta]], tblHelmet[[#This Row],[Base_sta]])) -> 2 | V26: =IF(tblHelmet[[#This Row],[Name]]="","", tblHelmet[[#This Row],[phy]]*Sheet1!$E$2 + tblHelmet[[#This Row],[mag]]*Sheet1!$F$2 + tblHelmet[[#This Row],[sta]]*Sheet1!$G$2) -> 6 | W26: =IF(tblHelmet[[#This Row],[Name]]="","", _xlfn.RANK.EQ(tblHelmet[[#This Row],[Score]], tblHelmet[Score], 0)) -> 17

Sheet body armor
A1: Name | B1: eng | C1: Drop | D1: Base_phy | E1: Base_mag | F1: Base_sta | G1: phy_cor | H1: phy_spi | I1: phy_gra | J1: mag_cor | K1: mag_spi | L1: mag_gra | M1: sta_cor | N1: sta_spi | O1: sta_gra | P1: min_cor | Q1: min_spi | R1: min_gra | S1: phy | T1: mag | U1: sta | V1: Score | W1: Rank
A2: 承种者腹甲 | B2: ARBEARER'S PAUNCHER | C2: 南瓜人 | D2: 7 | E2: 2 | F2: 4 | G2: 3 | J2: 1 | M2: 2 | P2: 22 | S2: =IF(tblBodyArmor[[#This Row],[Name]]="","", IF( AND( Sheet1!$A$2 >= tblBodyArmor[[#This Row],[min_cor]], Sheet1!$B$2 >= tblBodyArmor[[#This Row],[min_spi]], Sheet1!$C$2 >= tblBodyArmor[[#This Row],[min_gra]] ), _xlfn.FLOOR.MATH( value*tblBodyArmor[[#This Row],[phy_cor]]*Sheet1!$A$2 + value*tblBodyArmor[[#This Row],[phy_spi]]*Sheet1!$B$2 + value*tblBodyArmor[[#This Row],[phy_gra]]*Sheet1!$C$2 ) + tblBodyArmor[[#This Row],[Base_phy]], tblBodyArmor[[#This Row],[Base_phy]] )) -> 7 | T2: =IF(tblBodyArmor[[#This Row],[Name]]="","", IF(AND(Sheet1!$A$2>=tblBodyArmor[[#This Row],[min_cor]], Sheet1!$B$2>=tblBodyArmor[[#This Row],[min_spi]], Sheet1!$C$2>=tblBodyArmor[[#This Row],[min_gra]]), _xlfn.FLOOR.MATH(value*tblBodyArmor[[#This Row],[mag_cor]]*Sheet1!$A$2 + value*tblBodyArmor[[#This Row],[mag_spi]]*Sheet1!$B$2 + value*tblBodyArmor[[#This Row],[mag_gra]]*Sheet1!$C$2) + tblBodyArmor[[#This Row],[Base_mag]], tblBodyArmor[[#This Row],[Base_mag]])) -> 2 | U2: =IF(tblBodyArmor[[#This Row],[Name]]="","", IF(AND(Sheet1!$A$2>=tblBodyArmor[[#This Row],[min_cor]], Sheet1!$B$2>=tblBodyArmor[[#This Row],[min_spi]], Sheet1!$C$2>=tblBodyArmor[[#This Row],[min_gra]]), _xlfn.FLOOR.MATH(value*tblBodyArmor[[#This Row],[sta_cor]]*Sheet1!$A$2 + value*tblBodyArmor[[#This Row],[sta_spi]]*Sheet1!$B$2 + value*tblBodyArmor[[#This Row],[sta_gra]]*Sheet1!$C$2) + tblBodyArmor[[#This Row],[Base_sta]], tblBodyArmor[[#This Row],[Base_sta]])) -> 4 | V2: =IF(tblBodyArmor[[#This Row],[Name]]="","", tblBodyArmor[[#This Row],[phy]]*Sheet1!$E$2 + tblBodyArmor[[#This Row],[mag]]*Sheet1!$F$2 + tblBodyArmor[[#This Row],[sta]]*Sheet1!$G$2) -> 13 | W2: =IF(tblBodyArmor[[#This Row],[Name]]="","", _xlfn.RANK.EQ(tblBodyArmor[[#This Row],[Score]], tblBodyArmor[Score], 0)) -> 8
A3: 凯瑟德护腹 | B3: CIRCADE'S GUTGUARD | C3: 墓穴解密 | D3: 6 | E3: 0 | F3: 4 | G3: 3 | M3: 2 | P3: 14 | S3: =IF(tblBodyArmor[[#This Row],[Name]]="","", IF( AND( Sheet1!$A$2 >= tblBodyArmor[[#This Row],[min_cor]], Sheet1!$B$2 >= tblBodyArmor[[#This Row],[min_spi]], Sheet1!$C$2 >= tblBodyArmor[[#This Row],[min_gra]] ), _xlfn.FLOOR.MATH( value*tblBodyArmor[[#This Row],[phy_cor]]*Sheet1!$A$2 + value*tblBodyArmor[[#This Row],[phy_spi]]*Sheet1!$B$2 + value*tblBodyArmor[[#This Row],[phy_gra]]*Sheet1!$C$2 ) + tblBodyArmor[[#This Row],[Base_phy]], tblBodyArmor[[#This Row],[Base_phy]] )) -> 6 | T3: =IF(tblBodyArmor[[#This Row],[Name]]="","", IF(AND(Sheet1!$A$2>=tblBodyArmor[[#This Row],[min_cor]], Sheet1!$B$2>=tblBodyArmor[[#This Row],[min_spi]], Sheet1!$C$2>=tblBodyArmor[[#This Row],[min_gra]]), _xlfn.FLOOR.MATH(value*tblBodyArmor[[#This Row],[mag_cor]]*Sheet1!$A$2 + value*tblBodyArmor[[#This Row],[mag_spi]]*Sheet1!$B$2 + value*tblBodyArmor[[#This Row],[mag_gra]]*Sheet1!$C$2) + tblBodyArmor[[#This Row],[Base_mag]], tblBodyArmor[[#This Row],[Base_mag]])) -> 0 | U3: =IF(tblBodyArmor[[#This Row],[Name]]="","", IF(AND(Sheet1!$A$2>=tblBodyArmor[[#This Row],[min_cor]], Sheet1!$B$2>=tblBodyArmor[[#This Row],[min_spi]], Sheet1!$C$2>=tblBodyArmor[[#This Row],[min_gra]]), _xlfn.FLOOR.MATH(value*tblBodyArmor[[#This Row],[sta_cor]]*Sheet1!$A$2 + value*tblBodyArmor[[#This Row],[sta_spi]]*Sheet1!$B$2 + value*tblBodyArmor[[#This Row],[sta_gra]]*Sheet1!$C$2) + tblBodyArmor[[#This Row],[Base_sta]], tblBodyArmor[[#This Row],[Base_sta]])) -> 4 | V3: =IF(tblBodyArmor[[#This Row],[Name]]="","", tblBodyArmor[[#This Row],[phy]]*Sheet1!$E$2 + tblBodyArmor[[#This Row],[mag]]*Sheet1!$F$2 + tblBodyArmor[[#This Row],[sta]]*Sheet1!$G$2) -> 10 | W3: =IF(tblBodyArmor[[#This Row],[Name]]="","", _xlfn.RANK.EQ(tblBodyArmor[[#This Row],[Score]], tblBodyArmor[Score], 0)) -> 13
A4: 烈火之王铠甲 | B4: FIRE KING'S PLACKART | C4: 集团 | D4: 5 | E4: 2 | F4: 3 | G4: 2 | I4: 2 | J4: 1 | M4: 1 | O4: 2 | P4: 15 | S4: =IF(tblBodyArmor[[#This Row],[Name]]="","", IF( AND( Sheet1!$A$2 >= tblBodyArmor[[#This Row],[min_cor]], Sheet1!$B$2 >= tblBodyArmor[[#This Row],[min_spi]], Sheet1!$C$2 >= tblBodyArmor[[#This Row],[min_gra]] ), _xlfn.FLOOR.MATH( value*tblBodyArmor[[#This Row],[phy_cor]]*Sheet1!$A$2 + value*tblBodyArmor[[#This Row],[phy_spi]]*Sheet1!$B$2 + value*tblBodyArmor[[#This Row],[phy_gra]]*Sheet1!$C$2 ) + tblBodyArmor[[#This Row],[Base_phy]], tblBodyArmor[[#This Row],[Base_phy]] )) -> 5 | T4: =IF(tblBodyArmor[[#This Row],[Name]]="","", IF(AND(Sheet1!$A$2>=tblBodyArmor[[#This Row],[min_cor]], Sheet1!$B$2>=tblBodyArmor[[#This Row],[min_spi]], Sheet1!$C$2>=tblBodyArmor[[#This Row],[min_gra]]), _xlfn.FLOOR.MATH(value*tblBodyArmor[[#This Row],[mag_cor]]*Sheet1!$A$2 + value*tblBodyArmor[[#This Row],[mag_spi]]*Sheet1!$B$2 + value*tblBodyArmor[[#This Row],[mag_gra]]*Sheet1!$C$2) + tblBodyArmor[[#This Row],[Base_mag]], tblBodyArmor[[#This Row],[Base_mag]])) -> 2 | U4: =IF(tblBodyArmor[[#This Row],[Name]]="","", IF(AND(Sheet1!$A$2>=tblBodyArmor[[#This Row],[min_cor]], Sheet1!$B$2>=tblBodyArmor[[#This Row],[min_spi]], Sheet1!$C$2>=tblBodyArmor[[#This Row],[min_gra]]), _xlfn.FLOOR.MATH(value*tblBodyArmor[[#This Row],[sta_cor]]*Sheet1!$A$2 + value*tblBodyArmor[[#This Row],[sta_spi]]*Sheet1!$B$2 + value*tblBodyArmor[[#This Row],[sta_gra]]*Sheet1!$C$2) + tblBodyArmor[[#This Row],[Base_sta]], tblBodyArmor[[#This Row],[Base_sta]])) -> 3 | V4: =IF(tblBodyArmor[[#This Row],[Name]]="","", tblBodyArmor[[#This Row],[phy]]*Sheet1!$E$2 + tblBodyArmor[[#This Row],[mag]]*Sheet1!$F$2 + tblBodyArmor[[#This Row],[sta]]*Sheet1!$G$2) -> 10 | W4: =IF(tblBodyArmor[[#This Row],[Name]]="","", _xlfn.RANK.EQ(tblBodyArmor[[#This Row],[Score]], tblBodyArmor[Score], 0)) -> 13
A5: 忘焰皮衣 | B5: FORGETFIRE LEATHERS | C5: 集团 | D5: 4 | E5: 0 | F5: 3 | G5: 2 | M5: 2 | P5: 12 | S5: =IF(tblBodyArmor[[#This Row],[Name]]="","", IF( AND( Sheet1!$A$2 >= tblBodyArmor[[#This Row],[min_cor]], Sheet1!$B$2 >= tblBodyArmor[[#This Row],[min_spi]], Sheet1!$C$2 >= tblBodyArmor[[#This Row],[min_gra]] ), _xlfn.FLOOR.MATH( value*tblBodyArmor[[#This Row],[phy_cor]]*Sheet1!$A$2 + value*tblBodyArmor[[#This Row],[phy_spi]]*Sheet1!$B$2 + value*tblBodyArmor[[#This Row],[phy_gra]]*Sheet1!$C$2 ) + tblBodyArmor[[#This Row],[Base_phy]], tblBodyArmor[[#This Row],[Base_phy]] )) -> 4 | T5: =IF(tblBodyArmor[[#This Row],[Name]]="","", IF(AND(Sheet1!$A$2>=tblBodyArmor[[#This Row],[min_cor]], Sheet1!$B$2>=tblBodyArmor[[#This Row],[min_spi]], Sheet1!$C$2>=tblBodyArmor[[#This Row],[min_gra]]), _xlfn.FLOOR.MATH(value*tblBodyArmor[[#This Row],[mag_cor]]*Sheet1!$A$2 + value*tblBodyArmor[[#This Row],[mag_spi]]*Sheet1!$B$2 + value*tblBodyArmor[[#This Row],[mag_gra]]*Sheet1!$C$2) + tblBodyArmor[[#This Row],[Base_mag]], tblBodyArmor[[#This Row],[Base_mag]])) -> 0 | U5: =IF(tblBodyArmor[[#This Row],[Name]]="","", IF(AND(Sheet1!$A$2>=tblBodyArmor[[#This Row],[min_cor]], Sheet1!$B$2>=tblBodyArmor[[#This Row],[min_spi]], Sheet1!$C$2>=tblBodyArmor[[#This Row],[min_gra]]), _xlfn.FLOOR.MATH(value*tblBodyArmor[[#This Row],[sta_cor]]*Sheet1!$A$2 + value*tblBodyArmor[[#This Row],[sta_spi]]*Sheet1!$B$2 + value*tblBodyArmor[[#This Row],[sta_gra]]*Sheet1!$C$2) + tblBodyArmor[[#This Row],[Base_sta]], tblBodyArmor[[#This Row],[Base_sta]])) -> 3 | V5: =IF(tblBodyArmor[[#This Row],[Name]]="","", tblBodyArmor[[#This Row],[phy]]*Sheet1!$E$2 + tblBodyArmor[[#This Row],[mag]]*Sheet1!$F$2 + tblBodyArmor[[#This Row],[sta]]*Sheet1!$G$2) -> 7 | W5: =IF(tblBodyArmor[[#This Row],[Name]]="","", _xlfn.RANK.EQ(tblBodyArmor[[#This Row],[Score]], tblBodyArmor[Score], 0)) -> 19
A6: 赤裸 | B6: LAID BARE | C6: 初始 | D6: 0 | E6: 0 | F6: 0 | S6: =IF(tblBodyArmor[[#This Row],[Name]]="","", IF( AND( Sheet1!$A$2 >= tblBodyArmor[[#This Row],[min_cor]], Sheet1!$B$2 >= tblBodyArmor[[#This Row],[min_spi]], Sheet1!$C$2 >= tblBodyArmor[[#This Row],[min_gra]] ), _xlfn.FLOOR.MATH( value*tblBodyArmor[[#This Row],[phy_cor]]*Sheet1!$A$2 + value*tblBodyArmor[[#This Row],[phy_spi]]*Sheet1!$B$2 + value*tblBodyArmor[[#This Row],[phy_gra]]*Sheet1!$C$2 ) + tblBodyArmor[[#This Row],[Base_phy]], tblBodyArmor[[#This Row],[Base_phy]] )) -> 0 | T6: =IF(tblBodyArmor[[#This Row],[Name]]="","", IF(AND(Sheet1!$A$2>=tblBodyArmor[[#This Row],[min_cor]], Sheet1!$B$2>=tblBodyArmor[[#This Row],[min_spi]], Sheet1!$C$2>=tblBodyArmor[[#This Row],[min_gra]]), _xlfn.FLOOR.MATH(value*tblBodyArmor[[#This Row],[mag_cor]]*Sheet1!$A$2 + value*tblBodyArmor[[#This Row],[mag_spi]]*Sheet1!$B$2 + value*tblBodyArmor[[#This Row],[mag_gra]]*Sheet1!$C$2) + tblBodyArmor[[#This Row],[Base_mag]], tblBodyArmor[[#This Row],[Base_mag]])) -> 0 | U6: =IF(tblBodyArmor[[#This Row],[Name]]="","", IF(AND(Sheet1!$A$2>=tblBodyArmor[[#This Row],[min_cor]], Sheet1!$B$2>=tblBodyArmor[[#This Row],[min_spi]], Sheet1!$C$2>=tblBodyArmor[[#This Row],[min_gra]]), _xlfn.FLOOR.MATH(value*tblBodyArmor[[#This Row],[sta_cor]]*Sheet1!$A$2 + value*tblBodyArmor[[#This Row],[sta_spi]]*Sheet1!$B$2 + value*tblBodyArmor[[#This Row],[sta_gra]]*Sheet1!$C$2) + tblBodyArmor[[#This Row],[Base_sta]], tblBodyArmor[[#This Row],[Base_sta]])) -> 0 | V6: =IF(tblBodyArmor[[#This Row],[Name]]="","", tblBodyArmor[[#This Row],[phy]]*Sheet1!$E$2 + tblBodyArmor[[#This Row],[mag]]*Sheet1!$F$2 + tblBodyArmor[[#This Row],[sta]]*Sheet1!$G$2) -> 0 | W6: =IF(tblBodyArmor[[#This Row],[Name]]="","", _xlfn.RANK.EQ(tblBodyArmor[[#This Row],[Score]], tblBodyArmor[Score], 0)) -> 20
A7: 苦行者国王怨袍 | B7: MENDICANT KING'S SUIT OF RANCOR | C7: 乞王 | D7: 6 | E7: 3 | F7: 4 | G7: 3 | H7: 1 | J7: 1 | K7: 2 | M7: 1 | N7: 1 | P7: 20 | S7: =IF(tblBodyArmor[[#This Row],[Name]]="","", IF( AND( Sheet1!$A$2 >= tblBodyArmor[[#This Row],[min_cor]], Sheet1!$B$2 >= tblBodyArmor[[#This Row],[min_spi]], Sheet1!$C$2 >= tblBodyArmor[[#This Row],[min_gra]] ), _xlfn.FLOOR.MATH( value*tblBodyArmor[[#This Row],[phy_cor]]*Sheet1!$A$2 + value*tblBodyArmor[[#This Row],[phy_spi]]*Sheet1!$B$2 + value*tblBodyArmor[[#This Row],[phy_gra]]*Sheet1!$C$2 ) + tblBodyArmor[[#This Row],[Base_phy]], tblBodyArmor[[#This Row],[Base_phy]] )) -> 6 | T7: =IF(tblBodyArmor[[#This Row],[Name]]="","", IF(AND(Sheet1!$A$2>=tblBodyArmor[[#This Row],[min_cor]], Sheet1!$B$2>=tblBodyArmor[[#This Row],[min_spi]], Sheet1!$C$2>=tblBodyArmor[[#This Row],[min_gra]]), _xlfn.FLOOR.MATH(value*tblBodyArmor[[#This Row],[mag_cor]]*Sheet1!$A$2 + value*tblBodyArmor[[#This Row],[mag_spi]]*Sheet1!$B$2 + value*tblBodyArmor[[#This Row],[mag_gra]]*Sheet1!$C$2) + tblBodyArmor[[#This Row],[Base_mag]], tblBodyArmor[[#This Row],[Base_mag]])) -> 3 | U7: =IF(tblBodyArmor[[#This Row],[Name]]="","", IF(AND(Sheet1!$A$2>=tblBodyArmor[[#This Row],[min_cor]], Sheet1!$B$2>=tblBodyArmor[[#This Row],[min_spi]], Sheet1!$C$2>=tblBodyArmor[[#This Row],[min_gra]]), _xlfn.FLOOR.MATH(value*tblBodyArmor[[#This Row],[sta_cor]]*Sheet1!$A$2 + value*tblBodyArmor[[#This Row],[sta_spi]]*Sheet1!$B$2 + value*tblBodyArmor[[#This Row],[sta_gra]]*Sheet1!$C$2) + tblBodyArmor[[#This Row],[Base_sta]], tblBodyArmor[[#This Row],[Base_sta]])) -> 4 | V7: =IF(tblBodyArmor[[#This Row],[Name]]="","", tblBodyArmor[[#This Row],[phy]]*Sheet1!$E$2 + tblBodyArmor[[#This Row],[mag]]*Sheet1!$F$2 + tblBodyArmor[[#This Row],[sta]]*Sheet1!$G$2) -> 13 | W7: =IF(tblBodyArmor[[#This Row],[Name]]="","", _xlfn.RANK.EQ(tblBodyArmor[[#This Row],[Score]], tblBodyArmor[Score], 0)) -> 8
A8: 嘲魂束衣 | B8: MOCKERY BINDS | C8: 三重 | D8: 4 | E8: 4 | F8: 4 | H8: 2 | I8: 1 | K8: 2 | L8: 1 | N8: 1 | O8: 2 | R8: 20 | S8: =IF(tblBodyArmor[[#This Row],[Name]]="","", IF( AND( Sheet1!$A$2 >= tblBodyArmor[[#This Row],[min_cor]], Sheet1!$B$2 >= tblBodyArmor[[#This Row],[min_spi]], Sheet1!$C$2 >= tblBodyArmor[[#This Row],[min_gra]] ), _xlfn.FLOOR.MATH( value*tblBodyArmor[[#This Row],[phy_cor]]*Sheet1!$A$2 + value*tblBodyArmor[[#This Row],[phy_spi]]*Sheet1!$B$2 + value*tblBodyArmor[[#This Row],[phy_gra]]*Sheet1!$C$2 ) + tblBodyArmor[[#This Row],[Base_phy]], tblBodyArmor[[#This Row],[Base_phy]] )) -> 10 | T8: =IF(tblBodyArmor[[#This Row],[Name]]="","", IF(AND(Sheet1!$A$2>=tblBodyArmor[[#This Row],[min_cor]], Sheet1!$B$2>=tblBodyArmor[[#This Row],[min_spi]], Sheet1!$C$2>=tblBodyArmor[[#This Row],[min_gra]]), _xlfn.FLOOR.MATH(value*tblBodyArmor[[#This Row],[mag_cor]]*Sheet1!$A$2 + value*tblBodyArmor[[#This Row],[mag_spi]]*Sheet1!$B$2 + value*tblBodyArmor[[#This Row],[mag_gra]]*Sheet1!$C$2) + tblBodyArmor[[#This Row],[Base_mag]], tblBodyArmor[[#This Row],[Base_mag]])) -> 10 | U8: =IF(tblBodyArmor[[#This Row],[Name]]="","", IF(AND(Sheet1!$A$2>=tblBodyArmor[[#This Row],[min_cor]], Sheet1!$B$2>=tblBodyArmor[[#This Row],[min_spi]], Sheet1!$C$2>=tblBodyArmor[[#This Row],[min_gra]]), _xlfn.FLOOR.MATH(value*tblBodyArmor[[#This Row],[sta_cor]]*Sheet1!$A$2 + value*tblBodyArmor[[#This Row],[sta_spi]]*Sheet1!$B$2 + value*tblBodyArmor[[#This Row],[sta_gra]]*Sheet1!$C$2) + tblBodyArmor[[#This Row],[Base_sta]], tblBodyArmor[[#This Row],[Base_sta]])) -> 13 | V8: =IF(tblBodyArmor[[#This Row],[Name]]="","", tblBodyArmor[[#This Row],[phy]]*Sheet1!$E$2 + tblBodyArmor[[#This Row],[mag]]*Sheet1!$F$2 + tblBodyArmor[[#This Row],[sta]]*Sheet1!$G$2) -> 33 | W8: =IF(tblBodyArmor[[#This Row],[Name]]="","", _xlfn.RANK.EQ(tblBodyArmor[[#This Row],[Score]], tblBodyArmor[Score], 0)) -> 2
A9: 奥伦加胸甲 | B9: ORENGALL'S CUIRASS | C9: 集团 | D9: 5 | E9: 3 | F9: 4 | G9: 1 | I9: 3 | J9: 1 | L9: 1 | M9: 0 | O9: 3 | R9: 20 | S9: =IF(tblBodyArmor[[#This Row],[Name]]="","", IF( AND( Sheet1!$A$2 >= tblBodyArmor[[#This Row],[min_cor]], Sheet1!$B$2 >= tblBodyArmor[[#This Row],[min_spi]], Sheet1!$C$2 >= tblBodyArmor[[#This Row],[min_gra]] ), _xlfn.FLOOR.MATH( value*tblBodyArmor[[#This Row],[phy_cor]]*Sheet1!$A$2 + value*tblBodyArmor[[#This Row],[phy_spi]]*Sheet1!$B$2 + value*tblBodyArmor[[#This Row],[phy_gra]]*Sheet1!$C$2 ) + tblBodyArmor[[#This Row],[Base_phy]], tblBodyArmor[[#This Row],[Base_phy]] )) -> 19 | T9: =IF(tblBodyArmor[[#This Row],[Name]]="","", IF(AND(Sheet1!$A$2>=tblBodyArmor[[#This Row],[min_cor]], Sheet1!$B$2>=tblBodyArmor[[#This Row],[min_spi]], Sheet1!$C$2>=tblBodyArmor[[#This Row],[min_gra]]), _xlfn.FLOOR.MATH(value*tblBodyArmor[[#This Row],[mag_cor]]*Sheet1!$A$2 + value*tblBodyArmor[[#This Row],[mag_spi]]*Sheet1!$B$2 + value*tblBodyArmor[[#This Row],[mag_gra]]*Sheet1!$C$2) + tblBodyArmor[[#This Row],[Base_mag]], tblBodyArmor[[#This Row],[Base_mag]])) -> 8 | U9: =IF(tblBodyArmor[[#This Row],[Name]]="","", IF(AND(Sheet1!$A$2>=tblBodyArmor[[#This Row],[min_cor]], Sheet1!$B$2>=tblBodyArmor[[#This Row],[min_spi]], Sheet1!$C$2>=tblBodyArmor[[#This Row],[min_gra]]), _xlfn.FLOOR.MATH(value*tblBodyArmor[[#This Row],[sta_cor]]*Sheet1!$A$2 + value*tblBodyArmor[[#This Row],[sta_spi]]*Sheet1!$B$2 + value*tblBodyArmor[[#This Row],[sta_gra]]*Sheet1!$C$2) + tblBodyArmor[[#This Row],[Base_sta]], tblBodyArmor[[#This Row],[Base_sta]])) -> 17 | V9: =IF(tblBodyArmor[[#This Row],[Name]]="","", tblBodyArmor[[#This Row],[phy]]*Sheet1!$E$2 + tblBodyArmor[[#This Row],[mag]]*Sheet1!$F$2 + tblBodyArmor[[#This Row],[sta]]*Sheet1!$G$2) -> 44 | W9: =IF(tblBodyArmor[[#This Row],[Name]]="","", _xlfn.RANK.EQ(tblBodyArmor[[#This Row],[Score]], tblBodyArmor[Score], 0)) -> 1
